<?xml version="1.0" encoding="utf-8"?>
<!-- =================================================================================== -->
<!-- |    This document was autogenerated by xacro from main.xacro                     | -->
<!-- |    EDITING THIS FILE BY HAND IS NOT RECOMMENDED                                 | -->
<!-- =================================================================================== -->
<robot name="segway_robot">
  <!-- Wheel Mounting Positions -->
  <gazebo>
    <plugin filename="libgazebo_ros_control.so" name="gazebo_ros_control">
      <robotNamespace>/</robotNamespace>
    </plugin>
  </gazebo>
  <!-- Base link is the center of the robot's chassis between the motors -->
  <link name="base_link"/>
  <!-- Base footprint is on the ground under the robot -->
  <link name="base_chassis_link"/>
  <joint name="base_chassis_joint" type="fixed">
    <origin rpy="0 0 0" xyz="0 0 0.34925015"/>
    <parent link="base_link"/>
    <child link="base_chassis_link"/>
  </joint>
  <link name="inertial_collision_link">
    <inertial>
      <mass value="91.028000"/>
      <origin rpy="-1.570795 0 0" xyz="-0.033312 -0.001314 0.043167"/>
      <inertia ixx="2.625517" ixy="0.032260" ixz="-0.019196" iyx="0.032260" iyy="8.046165" iyz="-0.006618" izx="-0.019196" izy="-0.006618" izz="9.655358"/>
    </inertial>
    <collision>
      <origin rpy="0 0 0" xyz="0 0 0"/>
      <geometry>
        <mesh filename="440ECI_extented_chassis_collision.stl"/>
      </geometry>
    </collision>
  </link>
  <joint name="inertial_collision_joint" type="fixed">
    <parent link="base_chassis_link"/>
    <child link="inertial_collision_link"/>
  </joint>
  <joint name="front_chassis_joint" type="fixed">
    <origin rpy="0 0 3.14159" xyz="0.28575 0 0"/>
    <parent link="base_chassis_link"/>
    <child link="front_chassis_link"/>
  </joint>
  <link name="front_chassis_link">
    <visual>
      <geometry>
        <mesh filename="inv_gearbox_ext_spacer_chassis.dae"/>
      </geometry>
    </visual>
  </link>
  <joint name="rear_chassis_joint" type="fixed">
    <origin rpy="0 0 0" xyz="-0.28575 0 0"/>
    <parent link="base_chassis_link"/>
    <child link="rear_chassis_link"/>
  </joint>
  <link name="rear_chassis_link">
    <visual>
      <geometry>
        <mesh filename="inv_gearbox_ext_spacer_chassis.dae"/>
      </geometry>
    </visual>
  </link>
  <!-- Segway BSA Link (sign convention applied at embedded level)-->
  <link name="bsa_link"/>
  <joint name="bsa_joint" type="fixed">
    <origin rpy="0 0 0" xyz="0 0 0"/>
    <parent link="front_chassis_link"/>
    <child link="bsa_link"/>
  </joint>
  <gazebo reference="bsa_link"/>
  <joint name="mcu_0_battery_joint" type="fixed">
    <origin rpy="0 0 3.14159" xyz="0.37873 0 0"/>
    <parent link="base_chassis_link"/>
    <child link="mcu_0_battery_link"/>
  </joint>
  <link name="mcu_0_battery_link">
    <visual>
      <geometry>
        <mesh filename="battery.dae"/>
      </geometry>
    </visual>
  </link>
  <joint name="mcu_1_battery_joint" type="fixed">
    <origin rpy="0 0 0" xyz="0.19277 0 0"/>
    <parent link="base_chassis_link"/>
    <child link="mcu_1_battery_link"/>
  </joint>
  <link name="mcu_1_battery_link">
    <visual>
      <geometry>
        <mesh filename="battery.dae"/>
      </geometry>
    </visual>
  </link>
  <joint name="mcu_2_battery_joint" type="fixed">
    <origin rpy="0 0 3.14159" xyz="-0.19277 0 0"/>
    <parent link="base_chassis_link"/>
    <child link="mcu_2_battery_link"/>
  </joint>
  <link name="mcu_2_battery_link">
    <visual>
      <geometry>
        <mesh filename="battery.dae"/>
      </geometry>
    </visual>
  </link>
  <joint name="mcu_3_battery_joint" type="fixed">
    <origin rpy="0 0 0" xyz="-0.37873 0 0"/>
    <parent link="base_chassis_link"/>
    <child link="mcu_3_battery_link"/>
  </joint>
  <link name="mcu_3_battery_link">
    <visual>
      <geometry>
        <mesh filename="battery.dae"/>
      </geometry>
    </visual>
  </link>
  <joint name="eci_440_spacer_joint" type="fixed">
    <origin rpy="0 0 0" xyz="0 0 0"/>
    <parent link="base_chassis_link"/>
    <child link="eci_440_spacer_link"/>
  </joint>
  <link name="eci_440_spacer_link">
    <visual>
      <geometry>
        <mesh filename="440eci_spacers.dae"/>
      </geometry>
    </visual>
  </link>
  <joint name="rmp440_nave_brackets_joint" type="fixed">
    <origin rpy="0 0 0" xyz="0 0 0"/>
    <parent link="base_chassis_link"/>
    <child link="rmp440_nave_brackets_link"/>
  </joint>
  <link name="rmp440_nave_brackets_link">
    <visual>
      <geometry>
        <mesh filename="rmp440LE_NavE_brackets.dae"/>
      </geometry>
    </visual>
    <collision>
      <geometry>
        <mesh filename="rmp440LE_NavE_brackets.stl"/>
      </geometry>
    </collision>
  </link>
  <joint name="large_enclosure_joint" type="fixed">
    <origin rpy="0 0 0" xyz="0 0 0.05797"/>
    <parent link="base_chassis_link"/>
    <child link="large_enclosure_link"/>
  </joint>
  <link name="large_enclosure_link">
    <visual>
      <geometry>
        <mesh filename="large_enclosure.dae"/>
      </geometry>
    </visual>
  </link>
  <joint name="aux_battery_joint" type="fixed">
    <origin rpy="0 0 3.14159" xyz="0 0 0.03910"/>
    <parent link="base_chassis_link"/>
    <child link="aux_battery_link"/>
  </joint>
  <link name="aux_battery_link">
    <visual>
      <geometry>
        <mesh filename="battery.dae"/>
      </geometry>
    </visual>
  </link>
  <link name="front_left_wheel_link">
    <inertial>
      <mass value="7.030682"/>
      <origin xyz="0 0 0"/>
      <inertia ixx="0.140020" ixy="0.000000" ixz="0.000000" iyx="0.000000" iyy="0.250042" iyz="0.000000" izx="0.000000" izy="0.000000" izz="0.140020"/>
    </inertial>
    <visual>
      <origin rpy="0 0 0" xyz="0 0 0"/>
      <geometry>
        <mesh filename="x2_wheel.dae"/>
      </geometry>
    </visual>
    <collision>
      <origin rpy="1.570795 0 0" xyz="0 0 0"/>
      <geometry>
        <cylinder length="0.16" radius="0.2667"/>
      </geometry>
    </collision>
  </link>
  <gazebo reference="front_left_wheel_link">
    <mu1 value="1.0"/>
    <mu2 value="1.0"/>
    <kp value="8000000.0"/>
    <kd value="10.0"/>
    <fdir1 value="1 0 0"/>
  </gazebo>
  <joint name="front_left_wheel" type="continuous">
    <parent link="base_chassis_link"/>
    <child link="front_left_wheel_link"/>
    <origin rpy="0 0 0" xyz="0.28575 0.501211 -0.08255015"/>
    <axis rpy="0 0 0" xyz="0 1 0"/>
    <limit effort="1000.0" velocity="2000.0"/>
  </joint>
  <transmission name="front_left_wheel_trans" type="SimpleTransmission">
    <type>transmission_interface/SimpleTransmission</type>
    <actuator name="front_left_wheel_motor">
      <mechanicalReduction>1</mechanicalReduction>
    </actuator>
    <joint name="front_left_wheel">
      <hardwareInterface>VelocityJointInterface</hardwareInterface>
    </joint>
  </transmission>
  <link name="front_right_wheel_link">
    <inertial>
      <mass value="7.030682"/>
      <origin xyz="0 0 0"/>
      <inertia ixx="0.140020" ixy="0.000000" ixz="0.000000" iyx="0.000000" iyy="0.250042" iyz="0.000000" izx="0.000000" izy="0.000000" izz="0.140020"/>
    </inertial>
    <visual>
      <origin rpy="0 0 3.14159" xyz="0 0 0"/>
      <geometry>
        <mesh filename="x2_wheel.dae"/>
      </geometry>
    </visual>
    <collision>
      <origin rpy="1.570795 0 0" xyz="0 0 0"/>
      <geometry>
        <cylinder length="0.16" radius="0.2667"/>
      </geometry>
    </collision>
  </link>
  <gazebo reference="front_right_wheel_link">
    <mu1 value="1.0"/>
    <mu2 value="1.0"/>
    <kp value="8000000.0"/>
    <kd value="10.0"/>
    <fdir1 value="1 0 0"/>
  </gazebo>
  <joint name="front_right_wheel" type="continuous">
    <parent link="base_chassis_link"/>
    <child link="front_right_wheel_link"/>
    <origin rpy="0 0 0" xyz="0.28575 -0.501211 -0.08255015"/>
    <axis rpy="0 0 0" xyz="0 1 0"/>
    <limit effort="1000.0" velocity="2000.0"/>
  </joint>
  <transmission name="front_right_wheel_trans" type="SimpleTransmission">
    <type>transmission_interface/SimpleTransmission</type>
    <actuator name="front_right_wheel_motor">
      <mechanicalReduction>1</mechanicalReduction>
    </actuator>
    <joint name="front_right_wheel">
      <hardwareInterface>VelocityJointInterface</hardwareInterface>
    </joint>
  </transmission>
  <link name="rear_left_wheel_link">
    <inertial>
      <mass value="7.030682"/>
      <origin xyz="0 0 0"/>
      <inertia ixx="0.140020" ixy="0.000000" ixz="0.000000" iyx="0.000000" iyy="0.250042" iyz="0.000000" izx="0.000000" izy="0.000000" izz="0.140020"/>
    </inertial>
    <visual>
      <origin rpy="0 0 0" xyz="0 0 0"/>
      <geometry>
        <mesh filename="x2_wheel.dae"/>
      </geometry>
    </visual>
    <collision>
      <origin rpy="1.570795 0 0" xyz="0 0 0"/>
      <geometry>
        <cylinder length="0.16" radius="0.2667"/>
      </geometry>
    </collision>
  </link>
  <gazebo reference="rear_left_wheel_link">
    <mu1 value="1.0"/>
    <mu2 value="1.0"/>
    <kp value="8000000.0"/>
    <kd value="10.0"/>
    <fdir1 value="1 0 0"/>
  </gazebo>
  <joint name="rear_left_wheel" type="continuous">
    <parent link="base_chassis_link"/>
    <child link="rear_left_wheel_link"/>
    <origin rpy="0 0 0" xyz="-0.28575 0.501211 -0.08255015"/>
    <axis rpy="0 0 0" xyz="0 1 0"/>
    <limit effort="1000.0" velocity="2000.0"/>
  </joint>
  <transmission name="rear_left_wheel_trans" type="SimpleTransmission">
    <type>transmission_interface/SimpleTransmission</type>
    <actuator name="rear_left_wheel_motor">
      <mechanicalReduction>1</mechanicalReduction>
    </actuator>
    <joint name="rear_left_wheel">
      <hardwareInterface>VelocityJointInterface</hardwareInterface>
    </joint>
  </transmission>
  <link name="rear_right_wheel_link">
    <inertial>
      <mass value="7.030682"/>
      <origin xyz="0 0 0"/>
      <inertia ixx="0.140020" ixy="0.000000" ixz="0.000000" iyx="0.000000" iyy="0.250042" iyz="0.000000" izx="0.000000" izy="0.000000" izz="0.140020"/>
    </inertial>
    <visual>
      <origin rpy="0 0 3.14159" xyz="0 0 0"/>
      <geometry>
        <mesh filename="x2_wheel.dae"/>
      </geometry>
    </visual>
    <collision>
      <origin rpy="1.570795 0 0" xyz="0 0 0"/>
      <geometry>
        <cylinder length="0.16" radius="0.2667"/>
      </geometry>
    </collision>
  </link>
  <gazebo reference="rear_right_wheel_link">
    <mu1 value="1.0"/>
    <mu2 value="1.0"/>
    <kp value="8000000.0"/>
    <kd value="10.0"/>
    <fdir1 value="1 0 0"/>
  </gazebo>
  <joint name="rear_right_wheel" type="continuous">
    <parent link="base_chassis_link"/>
    <child link="rear_right_wheel_link"/>
    <origin rpy="0 0 0" xyz="-0.28575 -0.501211 -0.08255015"/>
    <axis rpy="0 0 0" xyz="0 1 0"/>
    <limit effort="1000.0" velocity="2000.0"/>
  </joint>
  <transmission name="rear_right_wheel_trans" type="SimpleTransmission">
    <type>transmission_interface/SimpleTransmission</type>
    <actuator name="rear_right_wheel_motor">
      <mechanicalReduction>1</mechanicalReduction>
    </actuator>
    <joint name="rear_right_wheel">
      <hardwareInterface>VelocityJointInterface</hardwareInterface>
    </joint>
  </transmission>
  <link name="ext_imu_frame"/>
  <joint name="ext_imu_joint" type="fixed">
    <origin rpy="0 0 3.1415" xyz="-0.2397 -0.1154 0.1899"/>
    <parent link="base_chassis_link"/>
    <child link="ext_imu_frame"/>
  </joint>
  <gazebo>
    <plugin filename="libhector_gazebo_ros_imu.so" name="imu_controller">
      <alwaysOn>1</alwaysOn>
      <updateRate>50.0</updateRate>
      <bodyName>ext_imu_frame</bodyName>
      <topicName>/segway/feedback/ext_imu</topicName>
      <accelDrift>0.005 0.005 0.005</accelDrift>
      <accelGaussianNoise>0.005 0.005 0.005</accelGaussianNoise>
      <rateDrift>0.005 0.005 0.005 </rateDrift>
      <rateGaussianNoise>0.005 0.005 0.005 </rateGaussianNoise>
      <headingDrift>0.005</headingDrift>
      <headingGaussianNoise>0.005</headingGaussianNoise>
    </plugin>
  </gazebo>
  <joint name="gps_joint" type="fixed">
    <origin rpy="0 0 0" xyz="0.3407 0.2585 0.2870"/>
    <parent link="base_chassis_link"/>
    <child link="gps_frame"/>
  </joint>
  <link name="gps_frame">
    <visual>
      <geometry>
        <mesh filename="garmin_18x_lvc_gps.dae"/>
      </geometry>
    </visual>
    <collision>
      <geometry>
        <mesh filename="garmin_18x_lvc_gps.stl"/>
      </geometry>
    </collision>
  </link>
  <gazebo>
    <plugin filename="libhector_gazebo_ros_gps.so" name="gps_controller">
      <alwaysOn>1</alwaysOn>
      <updateRate>40</updateRate>
      <bodyName>gps_frame</bodyName>
      <topicName>/segway/feedback/gps/fix_2d</topicName>
      <velocityTopicName>/segway/feedback/gps/vel</velocityTopicName>
      <referenceLatitude>40.712784</referenceLatitude>
      <referenceLongitude>-74.005941</referenceLongitude>
      <referenceHeading>0</referenceHeading>
      <referenceAltitude>0</referenceAltitude>
      <drift>0.0001 0.0001 0.0001</drift>
    </plugin>
  </gazebo>
  <joint name="camera_optical_joint" type="fixed">
    <origin rpy="0 0 0" xyz="0.3826 0.2268 0.2680"/>
    <parent link="base_chassis_link"/>
    <child link="camera_optical_frame"/>
  </joint>
  <link name="camera_optical_frame">
    <inertial>
      <mass value="0.107"/>
      <origin xyz="0 0 0"/>
      <inertia ixx="0.000080" ixy="0.0" ixz="0.0" iyx="0.0" iyy="0.000080" iyz="0.0" izx="0.0" izy="0.0" izz="0.000019"/>
    </inertial>
    <visual>
      <origin rpy="-1.570795 0 -1.570795"/>
      <geometry>
        <mesh filename="pgr_flea3.dae"/>
      </geometry>
    </visual>
    <collision>
      <origin rpy="-1.570795 0 -1.570795"/>
      <geometry>
        <mesh filename="pgr_flea3.stl"/>
      </geometry>
    </collision>
  </link>
  <gazebo reference="camera_optical_frame">
    <sensor name="flea3_camera_sensor" type="camera">
      <always_on>true</always_on>
      <update_rate>30.0</update_rate>
      <camera>
        <horizontal_fov>1.57777631111</horizontal_fov>
        <image>
          <format>R8G8B8</format>
          <width>640</width>
          <height>480</height>
        </image>
        <clip>
          <near>0.5</near>
          <far>100</far>
        </clip>
      </camera>
      <plugin filename="libgazebo_ros_camera.so" name="camera_controller">
        <alwaysOn>true</alwaysOn>
        <updateRate>25.0</updateRate>
        <cameraName>camera</cameraName>
        <imageTopicName>image_raw</imageTopicName>
        <cameraInfoTopicName>camera_info</cameraInfoTopicName>
        <frameName>/segway/camera_optical_frame</frameName>
        <hackBaseline>0</hackBaseline>
        <CxPrime>320.5</CxPrime>
        <Cx>320.5</Cx>
        <Cy>240.5</Cy>
        <!-- image_width / (2*tan(hfov_radian /2)) -->
        <!-- 320 for wide and 772.55 for narrow stereo camera -->
        <focalLength>317.772992</focalLength>
        <distortionK1>0.0</distortionK1>
        <distortionK2>0.0</distortionK2>
        <distortionK3>0.0</distortionK3>
        <distortionT1>0.0</distortionT1>
        <distortionT2>0.0</distortionT2>
      </plugin>
    </sensor>
  </gazebo>
</robot>

